Workbook
Name arc_inj_end_inj_y: Data!$S$17
Name arc_inj_end_inj_z: Data!$S$18
Name arc_inj_end_y: Data!$S$15
Name arc_inj_end_z: Data!$S$16
Name arc_inj_noz_y: Data!$V$17
Name arc_inj_noz_z: Data!$V$18
Name arc_inj_out_y: Data!$Y$17
Name arc_inj_out_z: Data!$Y$18
Name arc_inj_start_inj_y: Data!$P$17
Name arc_inj_start_inj_z: Data!$P$18
Name arc_inj_start_y: Data!$P$15
Name arc_inj_start_z: Data!$P$16
Name arc_inle_inj_y: Data!$J$17
Name arc_inle_inj_z: Data!$J$18
Name arc_inlet_y: Data!$J$15
Name arc_inlet_z: Data!$J$16
Name arc_noz_y: Data!$V$15
Name arc_noz_z: Data!$V$16
Name arc_out_y: Data!$Y$15
Name arc_out_z: Data!$Y$16
Name arc_throat_inj_y: Data!$M$17
Name arc_throat_inj_z: Data!$M$18
Name arc_throat_y: Data!$M$15
Name arc_throat_z: Data!$M$16
Name Gradient_end: Data!$B$39
Name Gradient_start: Data!$B$38
Name inj_height: Data!$F$10
Name inlet_inj: Data!$J$13
Name noz_inj_end: Data!$N$6
Name Nozzle_length: Data!$B$13
Name Nx_inj: Data!$B$31
Name Nx_noz_1: Data!$B$30
Name Nx_noz_2: Data!$B$32
Name NX_nozzle_total: Data!$B$12
Name Ny_center: Data!$B$34
Name Ny_outer: Data!$B$33
Name nz: Data!$B$35
Name outlet_inj: Data!$Q$6
Name pos_inj: Data!$B$7
Name pos_inj_back: Data!$K$3
Name pos_noz_end: Data!$N$3
Name pos_outlet: Data!$Q$3
Name position_inlet: Data!$B$11
Name radius_inj_end: Data!$K$4
Name radius_inj_start: Data!$F$6
Name radius_injector: Data!$B$3
Name radius_inlet: Data!$B$10
Name radius_noz_end: Data!$N$4
Name radius_outlet: Data!$Q$4
Name radius_throat: Data!$B$4
Name sqr_frac: Data!$B$8
Name sqr_frac_inj_end: Data!$K$5
Name sqr_frac_inlet: Data!$J$12
Name sqr_frac_noz_end: Data!$N$5
Name sqr_frac_outlet: Data!$Q$5
Name sqr_frac_throat: Data!$F$7
Name support_outlet: Data!$Y$14
Name support_wall_inj_end: Data!$S$14
Name support_wall_inj_start: Data!$P$14
Name support_wall_inlet: Data!$J$14

Sheet Data
A1: INPUT VALUES | E1: COMPUTED Values
E2: THROAT | H2: INJECTOR START | J2: INJECTOR END | M2: Nozzle end | P2: Outlet | S2: OuterRing
A3: radius_injector | B3: 0.001 | E3: throat_sqr | F3: =B4*B8 -> 0.0065 | J3: pos_inj_back | K3: =pos_inj+2*B3 -> 0.074 | M3: pos_noz_end | N3: =Nozzle_length -> 0.09 | P3: pos_outlet | Q3: =Nozzle_length*25 -> 2.25
A4: radius_throat | B4: 0.013 | E4: throat_inj_wall | F4: =SQRT(radius_throat^2-B3^2) -> 0.012961481 | J4: radius_inj_end | K4: =radius_throat+B14*(pos_inj+radius_injector) -> 0.025166667 | M4: radius_noz_end | N4: =B5 -> 0.028 | P4: radius_outlet | Q4: =radius_throat*40 -> 0.52
A5: radius_nozzle_exit | B5: 0.028 | E5: throat_support_wall | F5: =SQRT(radius_throat^2/2) -> 0.0091923882 | J5: sqr_frac_inj_end | K5: =radius_inj_end*sqr_frac -> 0.012583333 | M5: sqr_frac_noz_end | N5: =N4*sqr_frac -> 0.014 | P5: sqr_frac_outlet | Q5: =sqr_frac*Q4 -> 0.26
A6: percentage_injector | B6: 0.8 | E6: radius_inj_start | F6: =radius_throat+B14*pos_inj -> 0.025 | J6: throat_inj_wall_start | K6: =SQRT(radius_inj_start^2-radius_injector^2) -> 0.024979992 | M6: noz_inj_end | N6: =SQRT(radius_noz_end^2-(radius_injector*radius_noz_end/F6)^2) -> 0.027977591 | P6: outlet_inj | Q6: =SQRT(radius_outlet^2-(radius_injector*radius_outlet/radius_inj_end)^2) -> 0.51958933
A7: position_injector | B7: =Nozzle_length*B6 -> 0.072 | E7: sqr_frac_throat | F7: =sqr_frac*radius_throat -> 0.0065 | J7: throat_inj_wall_end | K7: =SQRT(radius_inj_end^2-radius_injector^2) -> 0.025146791 | M7: support_wall_noz_end | N7: =SQRT(radius_noz_end^2/2) -> 0.01979899 | P7: support_wall_outlet | Q7: =SQRT(radius_outlet^2/2) -> 0.36769553 | S7: support_wall_outer | T7: =SQRT(radius_outlet^2/2) -> 0.36769553
A8: sqr_frac | B8: 0.5 | J8: throat_support_wall_start | K8: =SQRT(radius_inj_start^2/2) -> 0.01767767
A9: injector from wall height | B9: 0.0005 | E9: INJECTOR | J9: throat_support_wall_end | K9: =SQRT(radius_inj_end^2/2) -> 0.017795521
A10: radius_inlet | B10: =40*radius_throat -> 0.52 | E10: inj_height | F10: =radius_inj_start+B9 -> 0.0255
A11: position_inlet | B11: =-Nozzle_length*25 -> -2.25 | I11: INLET | L11: THROAT | O11: Injector start
A12: NX_nozzle_total | B12: 500 | I12: sqr_frac_inlet | J12: =sqr_frac*radius_inlet -> 0.26
A13: Nozzle_length | B13: 0.09 | I13: inlet_inj | J13: =SQRT(radius_inlet^2-(radius_injector*radius_inlet/radius_inj_end)^2) -> 0.51958933
A14: slope_linearnozzle | B14: =(B5-radius_throat)/Nozzle_length -> 0.16666667 | I14: support_wall_inlet | J14: =SQRT(radius_inlet^2/2) -> 0.36769553 | L14: support_wall_throat | M14: =SQRT(radius_throat^2/2) -> 0.0091923882 | O14: support_wall_inj_start | P14: =SQRT(radius_inj_start^2/2) -> 0.01767767 | R14: support_wall_inj_end | S14: =SQRT(radius_inj_end^2/2) -> 0.017795521 | U14: support_wall_noz | V14: =SQRT(radius_noz_end^2/2) -> 0.01979899 | X14: support_outlet | Y14: =SQRT(radius_outlet^2/2) -> 0.36769553
A15: NZ_radial_total | B15: 20 | I15: arc_inlet_y | J15: =SQRT(radius_inlet^2-(support_wall_inlet/2)^2) -> 0.48641546 | L15: arc_throat_y | M15: =SQRT(radius_throat^2-(support_wall_throat/2)^2) -> 0.012160387 | O15: arc_inj_start_y | P15: =SQRT(radius_inj_start^2-(support_wall_inj_start/2)^2) -> 0.023385359 | R15: arc_inj_end_y | S15: =SQRT(radius_inj_end^2-(support_wall_inj_end/2)^2) -> 0.023541261 | U15: arc_noz_y | V15: =SQRT(radius_noz_end^2-(support_wall_noz/2)^2) -> 0.026191602 | X15: arc_out_y | Y15: =SQRT(radius_outlet^2-(support_outlet/2)^2) -> 0.48641546
A16: NY_tang_total | B16: 15 | I16: arc_inlet_z | J16: =-SQRT(radius_inlet^2-arc_inlet_y^2) -> -0.18384776 | L16: arc_throat_z | M16: =-SQRT(radius_throat^2-arc_throat_y^2) -> -0.0045961941 | O16: arc_inj_start_z | P16: =-SQRT(radius_inj_start^2-arc_inj_start_y^2) -> -0.0088388348 | R16: arc_inj_end_z | S16: =-SQRT(radius_inj_end^2-arc_inj_end_y^2) -> -0.0088977603 | U16: arc_noz_z | V16: =-SQRT(radius_noz_end^2-arc_noz_y^2) -> -0.0098994949 | X16: arc_out_z | Y16: =-SQRT(radius_outlet^2-arc_out_y^2) -> -0.18384776
I17: arc_inle_inj_y | J17: =SQRT(radius_inlet^2-arc_inle_inj_z^2) -> 0.51961524 | L17: arc_throat_inj_y | M17: =SQRT(radius_throat^2-arc_throat_inj_z^2) -> 0.012990381 | O17: arc_inj_start_inj_y | P17: =SQRT(radius_inj_start^2-P18^2) -> 0.024994999 | R17: arc_inj_end_inj_y | S17: =SQRT(radius_inj_end^2-arc_inj_end_inj_z^2) -> 0.025161699 | U17: arc_inj_noz_y | V17: =SQRT(radius_noz_end^2-arc_inj_noz_z^2) -> 0.027994399 | X17: arc_inj_out_y | Y17: =SQRT(radius_outlet^2-arc_inj_out_z^2) -> 0.51989599
I18: arc_inle_inj_z | J18: =-(radius_injector*radius_inlet/radius_throat)/2 -> -0.02 | L18: arc_throat_inj_z | M18: =-(radius_injector)/2 -> -0.0005 | O18: arc_inj_start_inj_z | P18: =-(radius_injector)/2 -> -0.0005 | R18: arc_inj_end_inj_z | S18: =-(radius_injector)/2 -> -0.0005 | U18: arc_inj_noz_z | V18: =-(radius_injector*radius_noz_end/radius_inj_start)/2 -> -0.00056 | X18: arc_inj_out_z | Y18: =-(radius_injector*radius_outlet/radius_inj_start)/2 -> -0.0104
A26: NX_entrance
A30: Nx_noz_1 | B30: =INT(pos_inj/Nozzle_length*NX_nozzle_total) -> 400
A31: Nx_inj | B31: 10
A32: Nx_noz_2 | B32: =NX_nozzle_total-B30 -> 100
A33: Ny_outer | B33: =INT(B15/3) -> 6
A34: Ny_center | B34: =B15/2 -> 10
A35: Nz | B35: =Ny_outer -> 6
A38: Gradient_start | B38: 0.001
A39: Gradient_end | B39: =1/B38 -> 1000

Sheet boundaries
A1: boundary
A2: (
B3: /*inlet
B4: {
B5: type | C5: patch;
B6: faces
B7: (
B8: (64 | C8: 68 | D8: 69 | E8: 65
B9: (68 | C9: 74 | D9: 72 | E9: 69
B10: (74 | C10: 75 | D10: 73 | E10: 72
B11: (69 | C11: 72 | D11: 73 | E11: 70
B12: (65 | C12: 69 | D12: 70 | E12: 66
B13: (70 | C13: 73 | D13: 75 | E13: 71
A14: (66 | B14: 70 | C14: 71 | D14: 67
B15: ;
B16: }
B18: outlet
B19: {
B20: type | C20: patch;
B21: faces
B22: (
B23: (48 | C23: 49 | D23: 53 | E23: 52
A24: (49 | B24: 50 | C24: 54 | D24: 53
A25: (50 | B25: 51 | C25: 55 | D25: 54
A26: (52 | B26: 53 | C26: 56 | D26: 58
A27: (56 | B27: 57 | C27: 59 | D27: 58
A28: (57 | B28: 54 | C28: 55 | D28: 59
A29: (53 | B29: 56 | C29: 57 | D29: 54
B30: ;
B31: }
B33: injection
B34: {
B35: type | C35: patch;
B36: faces
B37: (
B38: (63 | C38: 61 | D38: 60 | E38: 62
B39: ;
B40: }
A42: walls
A43: {
...

Sheet Vertices
A1: VERTICES
A3: ( | B3: 0 | C3: =radius_throat -> 0.013 | D3: 0 | E3: ) | F3: //0
A4: ( | B4: 0 | C4: =sqr_frac_throat -> 0.0065 | D4: 0 | E4: ) | F4: //1
A5: ( | B5: 0 | C5: =sqr_frac_throat -> 0.0065 | D5: =-Data!B3 -> -0.001 | E5: ) | F5: //2
A6: ( | B6: 0 | C6: =throat_inj_wall -> 0.012961481 | D6: =-Data!B3 -> -0.001 | E6: ) | F6: //3
A7: ( | B7: 0 | C7: =-Data!B4 -> -0.013 | D7: 0 | E7: ) | F7: //4
A8: ( | B8: 0 | C8: =-sqr_frac_throat -> -0.0065 | D8: 0 | E8: ) | F8: //5
A9: ( | B9: 0 | C9: =-sqr_frac_throat -> -0.0065 | D9: =-Data!B3 -> -0.001 | E9: ) | F9: //6
A10: ( | B10: 0 | C10: =-throat_inj_wall -> -0.012961481 | D10: =-Data!B3 -> -0.001 | E10: ) | F10: //7
A11: ( | B11: =pos_inj -> 0.072 | C11: =radius_inj_start -> 0.025 | D11: 0 | E11: ) | F11: //8
A12: ( | B12: =pos_inj -> 0.072 | C12: =sqr_frac_inj_end -> 0.012583333 | D12: 0 | E12: ) | F12: //9
A13: ( | B13: =pos_inj -> 0.072 | C13: =sqr_frac_inj_end -> 0.012583333 | D13: =-Data!B3 -> -0.001 | E13: ) | F13: //10
A14: ( | B14: =pos_inj -> 0.072 | C14: =throat_inj_wall_start -> 0.024979992 | D14: =-Data!B3 -> -0.001 | E14: ) | F14: //11
A15: ( | B15: =pos_inj -> 0.072 | C15: =-radius_inj_start -> -0.025 | D15: 0 | E15: ) | F15: //12
A16: ( | B16: =pos_inj -> 0.072 | C16: =-sqr_frac_inj_end -> -0.012583333 | D16: 0 | E16: ) | F16: //13
A17: ( | B17: =pos_inj -> 0.072 | C17: =-sqr_frac_inj_end -> -0.012583333 | D17: =-Data!B3 -> -0.001 | E17: ) | F17: //14
A18: ( | B18: =pos_inj -> 0.072 | C18: =-throat_inj_wall_start -> -0.024979992 | D18: =-Data!B3 -> -0.001 | E18: ) | F18: //15
A19: ( | B19: 0 | C19: =throat_sqr -> 0.0065 | D19: =-throat_sqr -> -0.0065 | E19: ) | F19: //16
A20: ( | B20: 0 | C20: =-throat_sqr -> -0.0065 | D20: =-throat_sqr -> -0.0065 | E20: ) | F20: //17
A21: ( | B21: =pos_inj -> 0.072 | C21: =sqr_frac_inj_end -> 0.012583333 | D21: =-sqr_frac_inj_end -> -0.012583333 | E21: ) | F21: //18
A22: ( | B22: =pos_inj -> 0.072 | C22: =-sqr_frac_inj_end -> -0.012583333 | D22: =-sqr_frac_inj_end -> -0.012583333 | E22: ) | F22: //19
A23: ( | B23: 0 | C23: =throat_support_wall -> 0.0091923882 | D23: =-throat_support_wall -> -0.0091923882 | E23: ) | F23: //20
A24: ( | B24: 0 | C24: =-throat_support_wall -> -0.0091923882 | D24: =-throat_support_wall -> -0.0091923882 | E24: ) | F24: //21
A25: ( | B25: =pos_inj -> 0.072 | C25: =throat_support_wall_start -> 0.01767767 | D25: =-throat_support_wall_start -> -0.01767767 | E25: ) | F25: //22
A26: ( | B26: =pos_inj -> 0.072 | C26: =-throat_support_wall_start -> -0.01767767 | D26: =-throat_support_wall_start -> -0.01767767 | E26: ) | F26: //23
A27: ( | B27: =pos_inj_back -> 0.074 | C27: =radius_inj_end -> 0.025166667 | D27: 0 | E27: ) | F27: //24
A28: ( | B28: =pos_inj_back -> 0.074 | C28: =sqr_frac_inj_end -> 0.012583333 | D28: 0 | E28: ) | F28: //25
A29: ( | B29: =pos_inj_back -> 0.074 | C29: =-sqr_frac_inj_end -> -0.012583333 | D29: 0 | E29: ) | F29: //26
A30: ( | B30: =pos_inj_back -> 0.074 | C30: =-radius_inj_end -> -0.025166667 | D30: 0 | E30: ) | F30: //27
A31: ( | B31: =pos_inj_back -> 0.074 | C31: =throat_inj_wall_end -> 0.025146791 | D31: =-radius_injector -> -0.001 | E31: ) | F31: //28
A32: ( | B32: =pos_inj_back -> 0.074 | C32: =sqr_frac_inj_end -> 0.012583333 | D32: =-radius_injector -> -0.001 | E32: ) | F32: //29
A33: ( | B33: =pos_inj_back -> 0.074 | C33: =-sqr_frac_inj_end -> -0.012583333 | D33: =-radius_injector -> -0.001 | E33: ) | F33: //30
A34: ( | B34: =pos_inj_back -> 0.074 | C34: =-throat_inj_wall_end -> -0.025146791 | D34: =-radius_injector -> -0.001 | E34: ) | F34: //31
A35: ( | B35: =pos_inj_back -> 0.074 | C35: =throat_support_wall_end -> 0.017795521 | D35: =-throat_support_wall_end -> -0.017795521 | E35: ) | F35: //32
A36: ( | B36: =pos_inj_back -> 0.074 | C36: =-throat_support_wall_end -> -0.017795521 | D36: =-throat_support_wall_end -> -0.017795521 | E36: ) | F36: //33
A37: ( | B37: =pos_inj_back -> 0.074 | C37: =sqr_frac_inj_end -> 0.012583333 | D37: =-sqr_frac_inj_end -> -0.012583333 | E37: ) | F37: //34
A38: ( | B38: =pos_inj_back -> 0.074 | C38: =-sqr_frac_inj_end -> -0.012583333 | D38: =-sqr_frac_inj_end -> -0.012583333 | E38: ) | F38: //35
A39: ( | B39: =pos_noz_end -> 0.09 | C39: =radius_noz_end -> 0.028 | D39: 0 | E39: ) | F39: //36
A40: ( | B40: =pos_noz_end -> 0.09 | C40: =sqr_frac_noz_end -> 0.014 | D40: 0 | E40: ) | F40: //37
A41: ( | B41: =pos_noz_end -> 0.09 | C41: =-sqr_frac_noz_end -> -0.014 | D41: 0 | E41: ) | F41: //38
...

Sheet hex
B1: hex | C1: ( | D1: 1 | E1: 9 | F1: 8 | G1: 0 | H1: 2 | I1: 10 | J1: 11 | K1: 3 | L1: ) | M1: ( | N1: =Nx_noz_1 -> 400 | O1: =Ny_outer -> 6 | P1: =nz -> 6 | Q1: ) | R1: simpleGrading ( | S1: 1 | T1: 1 | U1: 1 | V1: ) | W1: //0
B2: hex | C2: ( | D2: 5 | E2: 13 | F2: 9 | G2: 1 | H2: 6 | I2: 14 | J2: 10 | K2: 2 | L2: ) | M2: ( | N2: =Nx_noz_1 -> 400 | O2: =Ny_center -> 10 | P2: =nz -> 6 | Q2: ) | R2: simpleGrading ( | S2: 1 | T2: 1 | U2: 1 | V2: ) | W2: //1
B3: hex | C3: ( | D3: 4 | E3: 12 | F3: 13 | G3: 5 | H3: 7 | I3: 15 | J3: 14 | K3: 6 | L3: ) | M3: ( | N3: =Nx_noz_1 -> 400 | O3: =Ny_outer -> 6 | P3: =nz -> 6 | Q3: ) | R3: simpleGrading ( | S3: 1 | T3: 1 | U3: 1 | V3: ) | W3: //2
B4: hex | C4: ( | D4: 6 | E4: 14 | F4: 10 | G4: 2 | H4: 17 | I4: 19 | J4: 18 | K4: 16 | L4: ) | M4: ( | N4: =Nx_noz_1 -> 400 | O4: =Ny_center -> 10 | P4: =nz -> 6 | Q4: ) | R4: simpleGrading ( | S4: 1 | T4: 1 | U4: 1 | V4: ) | W4: //3
B5: hex | C5: ( | D5: 2 | E5: 10 | F5: 11 | G5: 3 | H5: 16 | I5: 18 | J5: 22 | K5: 20 | L5: ) | M5: ( | N5: =Nx_noz_1 -> 400 | O5: =Ny_outer -> 6 | P5: =nz -> 6 | Q5: ) | R5: simpleGrading ( | S5: 1 | T5: 1 | U5: 1 | V5: ) | W5: //4
B6: hex | C6: ( | D6: 17 | E6: 19 | F6: 18 | G6: 16 | H6: 21 | I6: 23 | J6: 22 | K6: 20 | L6: ) | M6: ( | N6: =Nx_noz_1 -> 400 | O6: =Ny_center -> 10 | P6: =Ny_outer -> 6 | Q6: ) | R6: simpleGrading ( | S6: 1 | T6: 1 | U6: 1 | V6: ) | W6: //5
B7: hex | C7: ( | D7: 7 | E7: 15 | F7: 14 | G7: 6 | H7: 21 | I7: 23 | J7: 19 | K7: 17 | L7: ) | M7: ( | N7: =Nx_noz_1 -> 400 | O7: =Ny_outer -> 6 | P7: =nz -> 6 | Q7: ) | R7: simpleGrading ( | S7: 1 | T7: 1 | U7: 1 | V7: ) | W7: //6
B8: hex | C8: ( | D8: 9 | E8: 25 | F8: 24 | G8: 8 | H8: 10 | I8: 29 | J8: 28 | K8: 11 | L8: ) | M8: ( | N8: =Nx_inj -> 10 | O8: =Ny_outer -> 6 | P8: =nz -> 6 | Q8: ) | R8: simpleGrading ( | S8: 1 | T8: 1 | U8: 1 | V8: ) | W8: //7
B9: hex | C9: ( | D9: 10 | E9: 29 | F9: 28 | G9: 11 | H9: 18 | I9: 34 | J9: 32 | K9: 22 | L9: ) | M9: ( | N9: =Nx_inj -> 10 | O9: =Ny_outer -> 6 | P9: =nz -> 6 | Q9: ) | R9: simpleGrading ( | S9: 1 | T9: 1 | U9: 1 | V9: ) | W9: //8
B10: hex | C10: ( | D10: 13 | E10: 26 | F10: 25 | G10: 9 | H10: 14 | I10: 30 | J10: 29 | K10: 10 | L10: ) | M10: ( | N10: =Nx_inj -> 10 | O10: =Ny_center -> 10 | P10: =nz -> 6 | Q10: ) | R10: simpleGrading ( | S10: 1 | T10: 1 | U10: 1 | V10: ) | W10: //9
B11: hex | C11: ( | D11: 12 | E11: 27 | F11: 26 | G11: 13 | H11: 15 | I11: 31 | J11: 30 | K11: 14 | L11: ) | M11: ( | N11: =Nx_inj -> 10 | O11: =Ny_outer -> 6 | P11: =nz -> 6 | Q11: ) | R11: simpleGrading ( | S11: 1 | T11: 1 | U11: 1 | V11: ) | W11: //10
B12: hex | C12: ( | D12: 14 | E12: 30 | F12: 29 | G12: 10 | H12: 19 | I12: 35 | J12: 34 | K12: 18 | L12: ) | M12: ( | N12: =Nx_inj -> 10 | O12: =Ny_center -> 10 | P12: =nz -> 6 | Q12: ) | R12: simpleGrading ( | S12: 1 | T12: 1 | U12: 1 | V12: ) | W12: //11
B13: hex | C13: ( | D13: 15 | E13: 31 | F13: 30 | G13: 14 | H13: 23 | I13: 33 | J13: 35 | K13: 19 | L13: ) | M13: ( | N13: =Nx_inj -> 10 | O13: =Ny_outer -> 6 | P13: =nz -> 6 | Q13: ) | R13: simpleGrading ( | S13: 1 | T13: 1 | U13: 1 | V13: ) | W13: //12
B14: hex | C14: ( | D14: 19 | E14: 35 | F14: 34 | G14: 18 | H14: 23 | I14: 33 | J14: 32 | K14: 22 | L14: ) | M14: ( | N14: =Nx_inj -> 10 | O14: =Ny_center -> 10 | P14: =Ny_outer -> 6 | Q14: ) | R14: simpleGrading ( | S14: 1 | T14: 1 | U14: 1 | V14: ) | W14: //13
B15: hex | C15: ( | D15: 25 | E15: 37 | F15: 36 | G15: 24 | H15: 29 | I15: 41 | J15: 40 | K15: 28 | L15: ) | M15: ( | N15: =Nx_noz_2 -> 100 | O15: =Ny_outer -> 6 | P15: =nz -> 6 | Q15: ) | R15: simpleGrading ( | S15: 1 | T15: 1 | U15: 1 | V15: ) | W15: //14
B16: hex | C16: ( | D16: 29 | E16: 41 | F16: 40 | G16: 28 | H16: 34 | I16: 44 | J16: 46 | K16: 32 | L16: ) | M16: ( | N16: =Nx_noz_2 -> 100 | O16: =Ny_outer -> 6 | P16: =nz -> 6 | Q16: ) | R16: simpleGrading ( | S16: 1 | T16: 1 | U16: 1 | V16: ) | W16: //15
B17: hex | C17: ( | D17: 26 | E17: 38 | F17: 37 | G17: 25 | H17: 30 | I17: 42 | J17: 41 | K17: 29 | L17: ) | M17: ( | N17: =Nx_noz_2 -> 100 | O17: =Ny_center -> 10 | P17: =nz -> 6 | Q17: ) | R17: simpleGrading ( | S17: 1 | T17: 1 | U17: 1 | V17: ) | W17: //16
B18: hex | C18: ( | D18: 27 | E18: 39 | F18: 38 | G18: 26 | H18: 31 | I18: 43 | J18: 42 | K18: 30 | L18: ) | M18: ( | N18: =Nx_noz_2 -> 100 | O18: =Ny_outer -> 6 | P18: =nz -> 6 | Q18: ) | R18: simpleGrading ( | S18: 1 | T18: 1 | U18: 1 | V18: ) | W18: //17
B19: hex | C19: ( | D19: 31 | E19: 43 | F19: 42 | G19: 30 | H19: 33 | I19: 47 | J19: 45 | K19: 35 | L19: ) | M19: ( | N19: =Nx_noz_2 -> 100 | O19: =Ny_outer -> 6 | P19: =nz -> 6 | Q19: ) | R19: simpleGrading ( | S19: 1 | T19: 1 | U19: 1 | V19: ) | W19: //18
B20: hex | C20: ( | D20: 30 | E20: 42 | F20: 41 | G20: 29 | H20: 35 | I20: 45 | J20: 44 | K20: 34 | L20: ) | M20: ( | N20: =Nx_noz_2 -> 100 | O20: =Ny_center -> 10 | P20: =nz -> 6 | Q20: ) | R20: simpleGrading ( | S20: 1 | T20: 1 | U20: 1 | V20: ) | W20: //19
B21: hex | C21: ( | D21: 35 | E21: 45 | F21: 44 | G21: 34 | H21: 33 | I21: 47 | J21: 46 | K21: 32 | L21: ) | M21: ( | N21: =Nx_noz_2 -> 100 | O21: =Ny_center -> 10 | P21: =Ny_outer -> 6 | Q21: ) | R21: simpleGrading ( | S21: 1 | T21: 1 | U21: 1 | V21: ) | W21: //20
B22: hex | C22: ( | D22: 37 | E22: 49 | F22: 48 | G22: 36 | H22: 41 | I22: 53 | J22: 52 | K22: 40 | L22: ) | M22: ( | N22: 10 | O22: =Ny_outer -> 6 | P22: =nz -> 6 | Q22: ) | R22: simpleGrading ( | S22: =Gradient_end -> 1000 | T22: 1 | U22: 1 | V22: ) | W22: //21
B23: hex | C23: ( | D23: 38 | E23: 50 | F23: 49 | G23: 37 | H23: 42 | I23: 54 | J23: 53 | K23: 41 | L23: ) | M23: ( | N23: 10 | O23: =Ny_center -> 10 | P23: =nz -> 6 | Q23: ) | R23: simpleGrading ( | S23: =Gradient_end -> 1000 | T23: 1 | U23: 1 | V23: ) | W23: //22
B24: hex | C24: ( | D24: 39 | E24: 51 | F24: 50 | G24: 38 | H24: 43 | I24: 55 | J24: 54 | K24: 42 | L24: ) | M24: ( | N24: 10 | O24: =Ny_outer -> 6 | P24: =nz -> 6 | Q24: ) | R24: simpleGrading ( | S24: =Gradient_end -> 1000 | T24: 1 | U24: 1 | V24: ) | W24: //23
B25: hex | C25: ( | D25: 41 | E25: 53 | F25: 52 | G25: 40 | H25: 44 | I25: 56 | J25: 58 | K25: 46 | L25: ) | M25: ( | N25: 10 | O25: =Ny_outer -> 6 | P25: =nz -> 6 | Q25: ) | R25: simpleGrading ( | S25: =Gradient_end -> 1000 | T25: 1 | U25: 1 | V25: ) | W25: //24
B26: hex | C26: ( | D26: 42 | E26: 54 | F26: 53 | G26: 41 | H26: 45 | I26: 57 | J26: 56 | K26: 44 | L26: ) | M26: ( | N26: 10 | O26: =Ny_center -> 10 | P26: =nz -> 6 | Q26: ) | R26: simpleGrading ( | S26: =Gradient_end -> 1000 | T26: 1 | U26: 1 | V26: ) | W26: //25
B27: hex | C27: ( | D27: 43 | E27: 55 | F27: 54 | G27: 42 | H27: 47 | I27: 59 | J27: 57 | K27: 45 | L27: ) | M27: ( | N27: 10 | O27: =Ny_outer -> 6 | P27: =nz -> 6 | Q27: ) | R27: simpleGrading ( | S27: =Gradient_end -> 1000 | T27: 1 | U27: 1 | V27: ) | W27: //26
B28: hex | C28: ( | D28: 45 | E28: 57 | F28: 56 | G28: 44 | H28: 47 | I28: 59 | J28: 58 | K28: 46 | L28: ) | M28: ( | N28: 10 | O28: =Ny_center -> 10 | P28: =Ny_outer -> 6 | Q28: ) | R28: simpleGrading ( | S28: =Gradient_end -> 1000 | T28: 1 | U28: 1 | V28: ) | W28: //27
B29: hex | C29: ( | D29: 8 | E29: 24 | F29: 61 | G29: 60 | H29: 11 | I29: 28 | J29: 63 | K29: 62 | L29: ) | M29: ( | N29: =Nx_inj -> 10 | O29: =Nx_inj -> 10 | P29: =nz -> 6 | Q29: ) | R29: simpleGrading ( | S29: 1 | T29: 10 | U29: 1 | V29: ) | W29: //28
B30: hex | C30: ( | D30: 65 | E30: 1 | F30: 0 | G30: 64 | H30: 69 | I30: 2 | J30: 3 | K30: 68 | L30: ) | M30: ( | N30: 10 | O30: =Ny_outer -> 6 | P30: =nz -> 6 | Q30: ) | R30: simpleGrading ( | S30: =Gradient_start -> 0.001 | T30: 1 | U30: 1 | V30: ) | W30: //29
B31: hex | C31: ( | D31: 66 | E31: 5 | F31: 1 | G31: 65 | H31: 70 | I31: 6 | J31: 2 | K31: 69 | L31: ) | M31: ( | N31: 10 | O31: =Ny_center -> 10 | P31: =nz -> 6 | Q31: ) | R31: simpleGrading ( | S31: =Gradient_start -> 0.001 | T31: 1 | U31: 1 | V31: ) | W31: //30
B32: hex | C32: ( | D32: 67 | E32: 4 | F32: 5 | G32: 66 | H32: 71 | I32: 7 | J32: 6 | K32: 70 | L32: ) | M32: ( | N32: 10 | O32: =Ny_outer -> 6 | P32: =nz -> 6 | Q32: ) | R32: simpleGrading ( | S32: =Gradient_start -> 0.001 | T32: 1 | U32: 1 | V32: ) | W32: //31
B33: hex | C33: ( | D33: 69 | E33: 2 | F33: 3 | G33: 68 | H33: 72 | I33: 16 | J33: 20 | K33: 74 | L33: ) | M33: ( | N33: 10 | O33: =Ny_outer -> 6 | P33: =nz -> 6 | Q33: ) | R33: simpleGrading ( | S33: =Gradient_start -> 0.001 | T33: 1 | U33: 1 | V33: ) | W33: //32
B34: hex | C34: ( | D34: 70 | E34: 6 | F34: 2 | G34: 69 | H34: 73 | I34: 17 | J34: 16 | K34: 72 | L34: ) | M34: ( | N34: 10 | O34: =Ny_center -> 10 | P34: =nz -> 6 | Q34: ) | R34: simpleGrading ( | S34: =Gradient_start -> 0.001 | T34: 1 | U34: 1 | V34: ) | W34: //33
B35: hex | C35: ( | D35: 71 | E35: 7 | F35: 6 | G35: 70 | H35: 75 | I35: 21 | J35: 17 | K35: 73 | L35: ) | M35: ( | N35: 10 | O35: =Ny_outer -> 6 | P35: =nz -> 6 | Q35: ) | R35: simpleGrading ( | S35: =Gradient_start -> 0.001 | T35: 1 | U35: 1 | V35: ) | W35: //34
B36: hex | C36: ( | D36: 73 | E36: 17 | F36: 16 | G36: 72 | H36: 75 | I36: 21 | J36: 20 | K36: 74 | L36: ) | M36: ( | N36: 10 | O36: =Ny_center -> 10 | P36: =Ny_outer -> 6 | Q36: ) | R36: simpleGrading ( | S36: =Gradient_start -> 0.001 | T36: 1 | U36: 1 | V36: ) | W36: //35
B38: hex | C38: ( | D38: 77 | E38: 36 | F38: 88 | G38: 76 | H38: 81 | I38: 40 | J38: 90 | K38: 80 | L38: ) | M38: ( | N38: 10 | O38: =Ny_center -> 10 | P38: =Ny_outer -> 6 | Q38: ) | R38: simpleGrading ( | S38: =Gradient_start -> 0.001 | T38: 1 | U38: 1 | V38: ) | W38: //36
B39: hex | C39: ( | D39: 81 | E39: 40 | F39: 90 | G39: 80 | H39: 84 | I39: 46 | J39: 92 | K39: 86 | L39: ) | M39: ( | N39: 10 | O39: =Ny_center -> 10 | P39: =Ny_outer -> 6 | Q39: ) | R39: simpleGrading ( | S39: =Gradient_start -> 0.001 | T39: 1 | U39: 1 | V39: ) | W39: //36
B40: hex | C40: ( | D40: 79 | E40: 89 | F40: 39 | G40: 78 | H40: 83 | I40: 91 | J40: 43 | K40: 82 | L40: ) | M40: ( | N40: 10 | O40: =Ny_center -> 10 | P40: =Ny_outer -> 6 | Q40: ) | R40: simpleGrading ( | S40: =Gradient_start -> 0.001 | T40: 1 | U40: 1 | V40: ) | W40: //36
B41: hex | C41: ( | D41: 83 | E41: 91 | F41: 43 | G41: 82 | H41: 87 | I41: 93 | J41: 47 | K41: 85 | L41: ) | M41: ( | N41: 10 | O41: =Ny_center -> 10 | P41: =Ny_outer -> 6 | Q41: ) | R41: simpleGrading ( | S41: =Gradient_start -> 0.001 | T41: 1 | U41: 1 | V41: ) | W41: //36
...

Sheet arcs
A1: arc | B1: 74 | C1: 68 | D1: ( | E1: =position_inlet -> -2.25 | F1: =arc_inlet_y -> 0.48641546 | G1: =arc_inlet_z -> -0.18384776 | H1: )
A2: arc | B2: 75 | C2: 74 | D2: ( | E2: =position_inlet -> -2.25 | F2: 0 | G2: =-radius_inlet -> -0.52 | H2: )
A3: arc | B3: 71 | C3: 75 | D3: ( | E3: =position_inlet -> -2.25 | F3: =-arc_inlet_y -> -0.48641546 | G3: =arc_inlet_z -> -0.18384776 | H3: )
A4: arc | B4: 67 | C4: 71 | D4: ( | E4: =position_inlet -> -2.25 | F4: =-arc_inle_inj_y -> -0.51961524 | G4: =arc_inle_inj_z -> -0.02 | H4: )
A5: arc | B5: 64 | C5: 68 | D5: ( | E5: =position_inlet -> -2.25 | F5: =arc_inle_inj_y -> 0.51961524 | G5: =arc_inle_inj_z -> -0.02 | H5: )
A6: arc | B6: 20 | C6: 3 | D6: ( | E6: 0 | F6: =arc_throat_y -> 0.012160387 | G6: =arc_throat_z -> -0.0045961941 | H6: )
A7: arc | B7: 21 | C7: 20 | D7: ( | E7: 0 | F7: 0 | G7: =-radius_throat -> -0.013 | H7: )
A8: arc | B8: 21 | C8: 7 | D8: ( | E8: 0 | F8: =-arc_throat_y -> -0.012160387 | G8: =arc_throat_z -> -0.0045961941 | H8: )
A9: arc | B9: 7 | C9: 4 | D9: ( | E9: 0 | F9: =-arc_throat_inj_y -> -0.012990381 | G9: =arc_throat_inj_z -> -0.0005 | H9: )
A10: arc | B10: 0 | C10: 3 | D10: ( | E10: 0 | F10: =arc_throat_inj_y -> 0.012990381 | G10: =arc_throat_inj_z -> -0.0005 | H10: )
A11: arc | B11: 22 | C11: 11 | D11: ( | E11: =pos_inj -> 0.072 | F11: =arc_inj_start_y -> 0.023385359 | G11: =arc_inj_start_z -> -0.0088388348 | H11: )
A12: arc | B12: 23 | C12: 22 | D12: ( | E12: =pos_inj -> 0.072 | F12: 0 | G12: =-radius_inj_start -> -0.025 | H12: )
A13: arc | B13: 23 | C13: 15 | D13: ( | E13: =pos_inj -> 0.072 | F13: =-arc_inj_start_y -> -0.023385359 | G13: =arc_inj_start_z -> -0.0088388348 | H13: )
A14: arc | B14: 18 | C14: 12 | D14: ( | E14: =pos_inj -> 0.072 | F14: =-arc_inj_start_inj_y -> -0.024994999 | G14: =arc_inj_start_inj_z -> -0.0005 | H14: )
A15: arc | B15: 8 | C15: 11 | D15: ( | E15: =pos_inj -> 0.072 | F15: =arc_inj_start_inj_y -> 0.024994999 | G15: =arc_inj_start_inj_z -> -0.0005 | H15: )
A16: arc | B16: 32 | C16: 28 | D16: ( | E16: =pos_inj_back -> 0.074 | F16: =arc_inj_end_y -> 0.023541261 | G16: =arc_inj_end_z -> -0.0088977603 | H16: )
A17: arc | B17: 33 | C17: 32 | D17: ( | E17: =pos_inj_back -> 0.074 | F17: 0 | G17: =-radius_inj_end -> -0.025166667 | H17: )
A18: arc | B18: 33 | C18: 31 | D18: ( | E18: =pos_inj_back -> 0.074 | F18: =-arc_inj_end_y -> -0.023541261 | G18: =arc_inj_end_z -> -0.0088977603 | H18: )
A19: arc | B19: 31 | C19: 27 | D19: ( | E19: =pos_inj_back -> 0.074 | F19: =-arc_inj_end_inj_y -> -0.025161699 | G19: =arc_inj_end_inj_z -> -0.0005 | H19: )
A20: arc | B20: 28 | C20: 24 | D20: ( | E20: =pos_inj_back -> 0.074 | F20: =arc_inj_end_inj_y -> 0.025161699 | G20: =arc_inj_end_inj_z -> -0.0005 | H20: )
A21: arc | B21: 46 | C21: 40 | D21: ( | E21: =pos_noz_end -> 0.09 | F21: =arc_noz_y -> 0.026191602 | G21: =arc_noz_z -> -0.0098994949 | H21: )
A22: arc | B22: 47 | C22: 46 | D22: ( | E22: =pos_noz_end -> 0.09 | F22: 0 | G22: =-radius_noz_end -> -0.028 | H22: )
A23: arc | B23: 47 | C23: 43 | D23: ( | E23: =pos_noz_end -> 0.09 | F23: =-arc_noz_y -> -0.026191602 | G23: =arc_noz_z -> -0.0098994949 | H23: )
A24: arc | B24: 43 | C24: 39 | D24: ( | E24: =pos_noz_end -> 0.09 | F24: =-arc_inj_noz_y -> -0.027994399 | G24: =arc_inj_noz_z -> -0.00056 | H24: )
A25: arc | B25: 40 | C25: 36 | D25: ( | E25: =pos_noz_end -> 0.09 | F25: =arc_inj_noz_y -> 0.027994399 | G25: =arc_inj_noz_z -> -0.00056 | H25: )
A26: arc | B26: 58 | C26: 52 | D26: ( | E26: =pos_outlet -> 2.25 | F26: =arc_out_y -> 0.48641546 | G26: =arc_out_z -> -0.18384776 | H26: )
A27: arc | B27: 59 | C27: 58 | D27: ( | E27: =pos_outlet -> 2.25 | F27: 0 | G27: =-radius_outlet -> -0.52 | H27: )
A28: arc | B28: 59 | C28: 55 | D28: ( | E28: =pos_outlet -> 2.25 | F28: =-arc_out_y -> -0.48641546 | G28: =arc_out_z -> -0.18384776 | H28: )
A29: arc | B29: 55 | C29: 51 | D29: ( | E29: =pos_outlet -> 2.25 | F29: =-arc_inj_out_y -> -0.51989599 | G29: =arc_inj_out_z -> -0.0104 | H29: )
A30: arc | B30: 52 | C30: 48 | D30: ( | E30: =pos_outlet -> 2.25 | F30: =arc_inj_out_y -> 0.51989599 | G30: =arc_inj_out_z -> -0.0104 | H30: )
D31: ( | H31: )
D32: ( | H32: )
D33: ( | H33: )
D34: ( | H34: )
D35: ( | H35: )
D36: ( | H36: )
D37: ( | H37: )
D38: ( | H38: )
H39: )
